Traceback (most recent call last):
  File "/usr/lib/python3.6/site-packages/requests/packages/urllib3/connection.py", line 142, in _new_conn
    (self.host, self.port), self.timeout, **extra_kw)
  File "/usr/lib/python3.6/site-packages/requests/packages/urllib3/util/connection.py", line 83, in create_connection
    raise err
  File "/usr/lib/python3.6/site-packages/requests/packages/urllib3/util/connection.py", line 73, in create_connection
    sock.connect(sa)
TimeoutError: [Errno 110] Connection timed out

During handling of the above exception, another exception occurred:

Traceback (most recent call last):
  File "/usr/lib/python3.6/site-packages/requests/packages/urllib3/connectionpool.py", line 600, in urlopen
    chunked=chunked)
  File "/usr/lib/python3.6/site-packages/requests/packages/urllib3/connectionpool.py", line 345, in _make_request
    self._validate_conn(conn)
  File "/usr/lib/python3.6/site-packages/requests/packages/urllib3/connectionpool.py", line 844, in _validate_conn
    conn.connect()
  File "/usr/lib/python3.6/site-packages/requests/packages/urllib3/connection.py", line 285, in connect
    conn = self._new_conn()
  File "/usr/lib/python3.6/site-packages/requests/packages/urllib3/connection.py", line 151, in _new_conn
    self, "Failed to establish a new connection: %s" % e)
requests.packages.urllib3.exceptions.NewConnectionError: <requests.packages.urllib3.connection.VerifiedHTTPSConnection object at 0x7f7d8a019048>: Failed to establish a new connection: [Errno 110] Connection timed out

During handling of the above exception, another exception occurred:

Traceback (most recent call last):
  File "/usr/lib/python3.6/site-packages/requests/adapters.py", line 423, in send
    timeout=timeout
  File "/usr/lib/python3.6/site-packages/requests/packages/urllib3/connectionpool.py", line 649, in urlopen
    _stacktrace=sys.exc_info()[2])
  File "/usr/lib/python3.6/site-packages/requests/packages/urllib3/util/retry.py", line 376, in increment
    raise MaxRetryError(_pool, url, error or ResponseError(cause))
requests.packages.urllib3.exceptions.MaxRetryError: HTTPSConnectionPool(host='yaledailynews.com', port=443): Max retries exceeded with url: /blog/2015/11/09/wilkinson-trying-times/ (Caused by NewConnectionError('<requests.packages.urllib3.connection.VerifiedHTTPSConnection object at 0x7f7d8a019048>: Failed to establish a new connection: [Errno 110] Connection timed out',))

During handling of the above exception, another exception occurred:

Traceback (most recent call last):
  File "YDN_article_read.py", line 103, in <module>
    complete_op_eds("ydn_op_eds_complete.txt", "ydn_oped_links_complete.csv")
  File "YDN_article_read.py", line 92, in complete_op_eds
    new = extract_text(link)
  File "YDN_article_read.py", line 43, in extract_text
    page = requests.get(url, headers=headers)
  File "/usr/lib/python3.6/site-packages/requests/api.py", line 70, in get
    return request('get', url, params=params, **kwargs)
  File "/usr/lib/python3.6/site-packages/requests/api.py", line 56, in request
    return session.request(method=method, url=url, **kwargs)
  File "/usr/lib/python3.6/site-packages/requests/sessions.py", line 488, in request
    resp = self.send(prep, **send_kwargs)
  File "/usr/lib/python3.6/site-packages/requests/sessions.py", line 609, in send
    r = adapter.send(request, **kwargs)
  File "/usr/lib/python3.6/site-packages/requests/adapters.py", line 487, in send
    raise ConnectionError(e, request=request)
requests.exceptions.ConnectionError: HTTPSConnectionPool(host='yaledailynews.com', port=443): Max retries exceeded with url: /blog/2015/11/09/wilkinson-trying-times/ (Caused by NewConnectionError('<requests.packages.urllib3.connection.VerifiedHTTPSConnection object at 0x7f7d8a019048>: Failed to establish a new connection: [Errno 110] Connection timed out',))
